Workbook
Name tblclub: 球队表格!$H$8
Name tblplayer: 球员数据库!$N$13

Sheet 球员数据库
A1: 球员名称 | B1: 年龄 | C1: 国家/地区籍 | D1: 身高 | E1: 体重 | F1: CA | G1: PA | H1: 位置 | I1: 年薪 | J1: 所在球队 | K1: 合约到期 | L1: 违约金 | M1: 合同类型 | N1: 合同备注 | O1: 命中行号 | Q1: 球员卡面 | R1: 球员卡身 | S1: 默认头像
A2: Daan van der Berg | B2: 32 | C2: 加西亚 | D2: 189 | E2: 82 | F2: 70 | G2: 72 | H2: 门将 | I2: 87 | J2: 自由球员 | L2: =I2*5 -> 435 | M2: 测试 | N2: 测试 | O2: =IF($J2=Sheet2!$A$2, ROW(), "") | Q2: https://i.pinimg.com/564x/89/b5/39/89b5392d6321520990ce45b123a24edc.jpg | S2: https://www.pesmaster.com/pes-2021-mobile/graphics/players/52326.png
A3: Joost van der Linden | B3: 36 | C3: 加西亚 | D3: 187 | E3: 80 | F3: 68 | G3: 69 | H3: 门将 | I3: 27 | J3: 自由球员 | L3: =I3*5 -> 135 | O3: =IF($J3=Sheet2!$A$2, ROW(), "") | Q3: https://i.pinimg.com/564x/89/b5/39/89b5392d6321520990ce45b123a25edc.jpg
A4: Lars de Wit | B4: 30 | C4: 加西亚 | D4: 192 | E4: 88 | F4: 70 | G4: 74 | H4: 中后卫 | I4: 127 | J4: 自由球员 | L4: =I4*5 -> 635 | O4: =IF($J4=Sheet2!$A$2, ROW(), "") | Q4: https://i.pinimg.com/564x/89/b5/39/89b5392d6321520990ce45b123a26edc.jpg
A5: Timo Bakker | B5: 33 | C5: 加西亚 | D5: 188 | E5: 85 | F5: 69 | G5: 71 | H5: 中后卫 | I5: 77 | J5: 自由球员 | L5: =I5*5 -> 385 | O5: =IF($J5=Sheet2!$A$2, ROW(), "") | Q5: https://i.pinimg.com/564x/89/b5/39/89b5392d6321520990ce45b123a27edc.jpg
A6: Bram Janssen | B6: 29 | C6: 加西亚 | D6: 183 | E6: 78 | F6: 70 | G6: 75 | H6: 右后卫 | I6: 137 | J6: 自由球员 | L6: =I6*5 -> 685 | O6: =IF($J6=Sheet2!$A$2, ROW(), "") | Q6: https://i.pinimg.com/564x/89/b5/39/89b5392d6321520990ce45b123a28edc.jpg
A7: Rens Verhoeven | B7: 31 | C7: 加西亚 | D7: 181 | E7: 75 | F7: 69 | G7: 72 | H7: 左后卫 | I7: 97 | J7: 自由球员 | L7: =I7*5 -> 485 | O7: =IF($J7=Sheet2!$A$2, ROW(), "") | Q7: https://i.pinimg.com/564x/89/b5/39/89b5392d6321520990ce45b123a29edc.jpg
A8: Siem van Dijk | B8: 34 | C8: 加西亚 | D8: 186 | E8: 83 | F8: 67 | G8: 68 | H8: 中后卫 | I8: 17 | J8: 自由球员 | L8: =I8*5 -> 85 | O8: =IF($J8=Sheet2!$A$2, ROW(), "") | Q8: https://i.pinimg.com/564x/89/b5/39/89b5392d6321520990ce45b123a30edc.jpg
A9: Luuk van der Meulen | B9: 28 | C9: 加西亚 | D9: 180 | E9: 77 | F9: 68 | G9: 75 | H9: 左后卫 | I9: 107 | J9: 自由球员 | L9: =I9*5 -> 535 | O9: =IF($J9=Sheet2!$A$2, ROW(), "") | Q9: https://i.pinimg.com/564x/89/b5/39/89b5392d6321520990ce45b123a31edc.jpg
A10: Thijs Mulder | B10: 32 | C10: 加西亚 | D10: 176 | E10: 72 | F10: 70 | G10: 71 | H10: 后腰 | I10: 117 | J10: 自由球员 | L10: =I10*5 -> 585 | O10: =IF($J10=Sheet2!$A$2, ROW(), "") | Q10: https://i.pinimg.com/564x/89/b5/39/89b5392d6321520990ce45b123a32edc.jpg
A11: Frenkie de Bruin | B11: 35 | C11: 加西亚 | D11: 178 | E11: 74 | F11: 68 | G11: 70 | H11: 组织中场 | I11: 67 | J11: 自由球员 | L11: =I11*5 -> 335 | O11: =IF($J11=Sheet2!$A$2, ROW(), "") | Q11: https://i.pinimg.com/564x/89/b5/39/89b5392d6321520990ce45b123a33edc.jpg
A12: Gijs van der Ven | B12: 30 | C12: 加西亚 | D12: 175 | E12: 70 | F12: 70 | G12: 74 | H12: 中前卫 | I12: 147 | J12: 自由球员 | L12: =I12*5 -> 735 | O12: =IF($J12=Sheet2!$A$2, ROW(), "") | Q12: https://i.pinimg.com/564x/89/b5/39/89b5392d6321520990ce45b123a34edc.jpg
A13: Mats de Lange | B13: 33 | C13: 加西亚 | D13: 179 | E13: 73 | F13: 68 | G13: 70 | H13: 右边锋 | I13: 87 | J13: 自由球员 | L13: =I13*5 -> 435 | O13: =IF($J13=Sheet2!$A$2, ROW(), "") | Q13: https://i.pinimg.com/564x/89/b5/39/89b5392d6321520990ce45b123a35edc.jpg
A14: Quinten van der Poel | B14: 29 | C14: 加西亚 | D14: 182 | E14: 78 | F14: 70 | G14: 74 | H14: 中锋 | I14: 157 | J14: 自由球员 | L14: =I14*5 -> 785 | O14: =IF($J14=Sheet2!$A$2, ROW(), "") | Q14: https://i.pinimg.com/564x/89/b5/39/89b5392d6321520990ce45b123a36edc.jpg
... A24: Viliame Kikau | B24: 31 | C24: 加西亚 | D24: 190 | E24: 98 | F24: 68 | G24: 71 | H24: 中锋 | I24: 97 | J24: 新法鲁大里斯本体育 | L24: =I24*5 -> 485 | O24: =IF($J24=Sheet2!$A$2, ROW(), "") | Q24: https://i.pinimg.com/564x/89/b5/39/89b5392d6321520990ce45b123a46edc.jpg
A25: Maika Sivo | B25: 33 | C25: 加西亚 | D25: 188 | E25: 93 | F25: 67 | G25: 68 | H25: 中锋 | I25: 47 | J25: 泰克马队 | K25: 3.5 | L25: =I25*5 -> 235 | M25: 全额保障 | O25: =IF($J25=Sheet2!$A$2, ROW(), "") | Q25: https://i.pinimg.com/564x/89/b5/39/89b5392d6321520990ce45b123a47edc.jpg
A26: Malakai Fekitoa | B26: 32 | C26: 加西亚 | D26: 187 | E26: 92 | F26: 69 | G26: 70 | H26: 影锋 | I26: 87 | J26: 新法鲁大里斯本体育 | L26: =I26*5 -> 435 | O26: =IF($J26=Sheet2!$A$2, ROW(), "") | Q26: https://i.pinimg.com/564x/89/b5/39/89b5392d6321520990ce45b123a48edc.jpg
A27: Jayden Tikoirotuma | B27: 29 | C27: 加西亚 | D27: 179 | E27: 78 | F27: 68 | G27: 73 | H27: 右边锋 | I27: 107 | J27: 新法鲁大里斯本体育 | L27: =I27*5 -> 535 | O27: =IF($J27=Sheet2!$A$2, ROW(), "") | Q27: https://i.pinimg.com/564x/89/b5/39/89b5392d6321520990ce45b123a49edc.jpg
A28: Tima Faingaʻanuku | B28: 28 | C28: 加西亚 | D28: 186 | E28: 89 | F28: 67 | G28: 74 | H28: 左边锋 | I28: 117 | J28: 新法鲁大里斯本体育 | L28: =I28*5 -> 585 | O28: =IF($J28=Sheet2!$A$2, ROW(), "") | Q28: https://i.pinimg.com/564x/89/b5/39/89b5392d6321520990ce45b123a50edc.jpg
A29: Peni Terepo | B29: 34 | C29: 加西亚 | D29: 192 | E29: 95 | F29: 67 | G29: 68 | H29: 中后卫 | I29: 37 | J29: 新法鲁大里斯本体育 | L29: =I29*5 -> 185 | O29: =IF($J29=Sheet2!$A$2, ROW(), "") | Q29: https://i.pinimg.com/564x/89/b5/39/89b5392d6321520990ce45b123a51edc.jpg
A30: Salesi Rayasi | B30: 30 | C30: 加西亚 | D30: 184 | E30: 87 | F30: 68 | G30: 72 | H30: 左后卫 | I30: 97 | J30: 新法鲁大里斯本体育 | L30: =I30*5 -> 485 | O30: =IF($J30=Sheet2!$A$2, ROW(), "") | Q30: https://i.pinimg.com/564x/89/b5/39/89b5392d6321520990ce45b123a52edc.jpg
A31: Pita Ahki | B31: 32 | C31: 加西亚 | D31: 182 | E31: 86 | F31: 67 | G31: 69 | H31: 中前卫 | I31: 67 | J31: 新法鲁大里斯本体育 | L31: =I31*5 -> 335 | O31: =IF($J31=Sheet2!$A$2, ROW(), "") | Q31: https://i.pinimg.com/564x/89/b5/39/89b5392d6321520990ce45b123a53edc.jpg
A32: Rieko Mavaega | B32: 27 | C32: 加西亚 | D32: 185 | E32: 90 | F32: 66 | G32: 74 | H32: 中后卫 | I32: 97 | J32: 新法鲁大里斯本体育 | L32: =I32*5 -> 485 | O32: =IF($J32=Sheet2!$A$2, ROW(), "") | Q32: https://i.pinimg.com/564x/89/b5/39/89b5392d6321520990ce45b123a54edc.jpg
A33: Ardie Savea | B33: 31 | C33: 加西亚 | D33: 181 | E33: 83 | F33: 69 | G33: 71 | H33: 后腰 | I33: 107 | J33: 新法鲁大里斯本体育 | L33: =I33*5 -> 535 | O33: =IF($J33=Sheet2!$A$2, ROW(), "") | Q33: https://i.pinimg.com/564x/89/b5/39/89b5392d6321520990ce45b123a55edc.jpg
A34: Akash Sharma | B34: 30 | C34: 加西亚 | D34: 178 | E34: 75 | F34: 68 | G34: 72 | H34: 组织中场 | I34: 87 | J34: 新法鲁大里斯本体育 | L34: =I34*5 -> 435 | O34: =IF($J34=Sheet2!$A$2, ROW(), "") | Q34: https://i.pinimg.com/564x/89/b5/39/89b5392d6321520990ce45b123a56edc.jpg
A35: Vasco Correia | B35: 33 | C35: 加西亚 | D35: 180 | E35: 78 | F35: 68 | G35: 69 | H35: 左后卫 | I35: 67 | J35: 新法鲁大里斯本体育 | L35: =I35*5 -> 335 | O35: =IF($J35=Sheet2!$A$2, ROW(), "") | Q35: https://i.pinimg.com/564x/89/b5/39/89b5392d6321520990ce45b123a57edc.jpg
A36: Rohan Patel | B36: 29 | C36: 加西亚 | D36: 175 | E36: 70 | F36: 69 | G36: 73 | H36: 进攻中场 | I36: 117 | J36: 新法鲁大里斯本体育 | L36: =I36*5 -> 585 | O36: =IF($J36=Sheet2!$A$2, ROW(), "") | Q36: https://i.pinimg.com/564x/89/b5/39/89b5392d6321520990ce45b123a58edc.jpg
A37: Paulo Lopes | B37: 34 | C37: 加西亚 | D37: 183 | E37: 81 | F37: 66 | G37: 67 | H37: 门将 | I37: 17 | J37: 新法鲁大里斯本体育 | L37: =I37*5 -> 85 | O37: =IF($J37=Sheet2!$A$2, ROW(), "") | Q37: https://i.pinimg.com/564x/89/b5/39/89b5392d6321520990ce45b123a59edc.jpg
... A76: Josua Vakurunabili | B76: 27 | C76: 加西亚 | D76: 187 | E76: 92 | F76: 65 | G76: 72 | H76: 门将 | I76: 25 | J76: 伊斯特伍德竞技 | L76: =I76*5 -> 125 | O76: =IF($J76=Sheet2!$A$2, ROW(), "") | Q76: https://i.pinimg.com/564x/89/b5/39/89b5392d6321520990ce45b123a98edc.jpg
A77: Leone Nakarawa | B77: 32 | C77: 加西亚 | D77: 197 | E77: 104 | F77: 68 | G77: 69 | H77: 中后卫 | I77: 24 | J77: 伊斯特伍德竞技 | K77: 2.5 | L77: =I77*5 -> 120 | M77: 全额保障 | O77: =IF($J77=Sheet2!$A$2, ROW(), "") | Q77: https://i.pinimg.com/564x/89/b5/39/89b5392d6321520990ce45b123a99edc.jpg
A78: Tevita Cavubati | B78: 28 | C78: 加西亚 | D78: 193 | E78: 98 | F78: 65 | G78: 71 | H78: 中后卫 | I78: 35 | J78: 伊斯特伍德竞技 | L78: =I78*5 -> 175 | O78: =IF($J78=Sheet2!$A$2, ROW(), "") | Q78: https://i.pinimg.com/564x/89/b5/39/89b5392d6321520990ce45b123a100edc.jpg
A79: Mesake Doge | B79: 31 | C79: 加西亚 | D79: 191 | E79: 100 | F79: 67 | G79: 69 | H79: 右后卫 | I79: 24 | J79: 伊斯特伍德竞技 | K79: 2.5 | L79: =I79*5 -> 120 | M79: 全额保障 | O79: =IF($J79=Sheet2!$A$2, ROW(), "") | Q79: https://i.pinimg.com/564x/89/b5/39/89b5392d6321520990ce45b123a101edc.jpg
A80: Josh Matavesi | B80: 30 | C80: 加西亚 | D80: 185 | E80: 90 | F80: 66 | G80: 70 | H80: 左边锋 | I80: 24 | J80: 伊斯特伍德竞技 | K80: 2.5 | L80: =I80*5 -> 120 | M80: 半保障 | O80: =IF($J80=Sheet2!$A$2, ROW(), "") | Q80: https://i.pinimg.com/564x/89/b5/39/89b5392d6321520990ce45b123a102edc.jpg
A81: Richard Hughes | B81: 33 | C81: 加西亚 | D81: 183 | E81: 85 | F81: 65 | G81: 70 | H81: 左后卫 | I81: 27 | J81: 比斯恰捍卫者 | L81: =I81*5 -> 135 | O81: =IF($J81=Sheet2!$A$2, ROW(), "") | Q81: https://i.pinimg.com/564x/89/b5/39/89b5392d6321520990ce45b123a103edc.jpg
A82: Steven Gilmour | B82: 34 | C82: 加西亚 | D82: 178 | E82: 80 | F82: 66 | G82: 69 | H82: 组织中场 | I82: 47 | J82: 比斯恰捍卫者 | L82: =I82*5 -> 235 | O82: =IF($J82=Sheet2!$A$2, ROW(), "") | Q82: https://i.pinimg.com/564x/89/b5/39/89b5392d6321520990ce45b123a104edc.jpg
A83: Andrew Thornton | B83: 33 | C83: 加西亚 | D83: 177 | E83: 79 | F83: 66 | G83: 70 | H83: 进攻中场 | I83: 27 | J83: 比斯恰捍卫者 | L83: =I83*5 -> 135 | O83: =IF($J83=Sheet2!$A$2, ROW(), "") | Q83: https://i.pinimg.com/564x/89/b5/39/89b5392d6321520990ce45b123a105edc.jpg
A84: Kevin Hargreaves | B84: 34 | C84: 加西亚 | D84: 181 | E84: 84 | F84: 66 | G84: 69 | H84: 左边锋 | I84: 47 | J84: 比斯恰捍卫者 | L84: =I84*5 -> 235 | O84: =IF($J84=Sheet2!$A$2, ROW(), "") | Q84: https://i.pinimg.com/564x/89/b5/39/89b5392d6321520990ce45b123a106edc.jpg
A85: Nigel Davenport | B85: 37 | C85: 加西亚 | D85: 185 | E85: 87 | F85: 68 | G85: 68 | H85: 中锋 | I85: 67 | J85: 比斯恰捍卫者 | L85: =I85*5 -> 335 | O85: =IF($J85=Sheet2!$A$2, ROW(), "") | Q85: https://i.pinimg.com/564x/89/b5/39/89b5392d6321520990ce45b123a107edc.jpg
A86: Colin Ramsey | B86: 32 | C86: 加西亚 | D86: 182 | E86: 84 | F86: 65 | G86: 70 | H86: 右边锋 | I86: 17 | J86: 比斯恰捍卫者 | L86: =I86*5 -> 85 | O86: =IF($J86=Sheet2!$A$2, ROW(), "") | Q86: https://i.pinimg.com/564x/89/b5/39/89b5392d6321520990ce45b123a108edc.jpg
A87: Derek Sutton | B87: 37 | C87: 加西亚 | D87: 186 | E87: 87 | F87: 67 | G87: 68 | H87: 后腰 | I87: 57 | J87: 比斯恰捍卫者 | K87: 1 | L87: =I87*5 -> 285 | O87: =IF($J87=Sheet2!$A$2, ROW(), "") | Q87: https://i.pinimg.com/564x/89/b5/39/89b5392d6321520990ce45b123a109edc.jpg
...

Sheet 球队表格
A1: 球队名 | B1: 玩家 | C1: 教练组 | D1: 主场 | E1: 座席数 | F1: 场均上座 | G1: 上座率 | H1: 收入 | I1: 球队资金 | J1: 赞助商1 | K1: 赞助商2 | L1: 青训 | M1: 其他
A2: 马雷克青春之城 | B2: 玩家：抖音kolo | C2: 康宁汉姆、[进攻]R-富勒、[战术]J-利略、[门将]波纳伊迪、[防守]莫纳克、[体能]蒙特罗、[青训]罗斯科 | D2: 马雷克奥体中心 | E2: 15000 | F2: 9228 | G2: =表2[[#This Row],[场均上座]]/表2[[#This Row],[座席数]] -> 0.6152 | H2: =表2[[#This Row],[场均上座]]*95*20 -> 17533200 | I2: 1103 | J2: 马雷克商业银行 600 | K2: 马雷克省投控 600 | L2: 22 | M2: 球探等级：10
A3: 南太平洋大学色温校区 | B3: 玩家：你哈哥 黄教授 | C3: 蔡德勒、[助教]金东进、[助教]李光宰、[体能]J-万德雷、[战术]李正孝、[门将]金贤拱、[总监]金城南 | D3: 新泰体育中心专业足球场 | E3: 30000 | F3: 9195 | G3: =表2[[#This Row],[场均上座]]/表2[[#This Row],[座席数]] -> 0.3065 | H3: =表2[[#This Row],[场均上座]]*95*20 -> 17470500 | I3: 3259 | J3: 东平县金控集团 700 | L3: 60 | M3: 可征战世大运
A4: 三宝敦 | B4: 玩家: 抖音@66 | C4: 伊塔里亚诺、[助教]罗塞蒂、[助教]尼克里诺、[分析师]德尔奥迪、[总监]J-萨托利、[体能]N-普兰德利、[经理]马洛塔 | D4: 新阿尔米利亚提公园球场 | E4: 10000 | F4: 9468 | G4: =表2[[#This Row],[场均上座]]/表2[[#This Row],[座席数]] -> 0.9468 | H4: =表2[[#This Row],[场均上座]]*95*20 -> 17989200 | I4: 5990 | J4: 加西亚华人商会 1300 | K4: 中海外 1300 | L4: 5 | M4: /
A5: 皇家萨乌萨乌 | B5: 玩家: 小律 | C5: 于根伟、[助教]埃斯特万、[助教]哈维尔、[体能]J-加维兰、[门将]王略、[门将]昆戴、[分析]J-赫塞 | D5: 里拉赫球场 | E5: 3500 | F5: 128 | G5: =表2[[#This Row],[场均上座]]/表2[[#This Row],[座席数]] -> 0.036571429 | H5: =表2[[#This Row],[场均上座]]*95*20 -> 243200 | I5: 3600 | J5: 里拉赫县议会 | M5: /
A6: 安倍萨镇 | B6: 玩家: 阿古 | C6: 米龙·穆斯利奇、伯格斯塔勒、赫韦德斯 | D6: 安倍萨足球场 | E6: 250 | F6: 76 | G6: =表2[[#This Row],[场均上座]]/表2[[#This Row],[座席数]] -> 0.304 | H6: =表2[[#This Row],[场均上座]]*95*20 -> 144400 | I6: 2964 | L6: 2 | M6: /
A7: 哈贾丹太平洋人 | B7: 玩家：墩子 | C7: 拉尔斯·拉格贝克、[分析]M-图洛尼、[助教]A-拉尼、[门将]M-特拉维萨、[经理]西格伊尔松、[助教]达尔蒙特、[队医]D-阿维 | D7: 哈贾丹橄榄球场 | E7: 700 | F7: 582 | G7: =表2[[#This Row],[场均上座]]/表2[[#This Row],[座席数]] -> 0.83142857 | H7: =表2[[#This Row],[场均上座]]*95*20 -> 1105800 | I7: 1050 | J7: 加西亚穆斯林商会 500 | L7: 10 | M7: /
A8: 首都守护者 | B8: 玩家：抖音577842845 | C8: J-勒夫、[助教]克林斯曼、[助教]M-索尔格、[助教]布瓦茨、[门将]科普克、[队医]沃尔法特、[青训]萨莫尔 | D8: 总统国立竞技场 | E8: 30000 | F8: 29938 | G8: =表2[[#This Row],[场均上座]]/表2[[#This Row],[座席数]] -> 0.99793333 | H8: =表2[[#This Row],[场均上座]]*95*20 -> 56882200 | I8: 7223 | J8: 国家糖业集团 1200 | K8: 国家能投 1200 | M8: /
A9: 比列竞技 | B9: 玩家: 抖音@宾 | C9: 里卡多-罗德里格斯 | D9: 乌克斯布里德竞技场 | E9: 15000 | F9: 0 | G9: =表2[[#This Row],[场均上座]]/表2[[#This Row],[座席数]] -> 0 | H9: =表2[[#This Row],[场均上座]]*95*20 -> 0 | I9: 382 | M9: /
A10: 瓦巴萨朱树鸦 | B10: 玩家: 云龙 | C10: 克努特森、[分析]E-科斯塔德、[助教]高特、[门将]J-科斯塔德、[队医]曼斯维克、[总监]哈瓦尔德 | D10: 瓦巴萨朱运动场 | E10: 10000 | F10: 3884 | G10: =表2[[#This Row],[场均上座]]/表2[[#This Row],[座席数]] -> 0.3884 | H10: =表2[[#This Row],[场均上座]]*95*20 -> 7379600 | I10: 3680 | J10: 瓦巴萨朱市议会 600 | K10: 瓦巴萨朱大学 400 | L10: 20 | M10: 球探等级：5
A11: 穆拉哈西部 | B11: 玩家: 抖音春飘雨 | C11: 卢塞斯库、[分析师]普拉托夫、[助教]V-戈麦斯、[助教]A-博斯、[门将]库扎莫夫、[体能]V-库列巴、[总监]卢日尼 | D11: 穆拉哈体育场 | E11: 700 | F11: 700 | G11: =表2[[#This Row],[场均上座]]/表2[[#This Row],[座席数]] -> 1 | H11: =表2[[#This Row],[场均上座]]*95*20 -> 1330000 | I11: 831 | J11: 穆拉哈啤酒 400 | K11: 穆拉哈省议会 300 | L11: 20 | M11: /
A12: 巴峰 | B12: 玩家:抖音1.1595 | C12: F-卡纳瓦罗、[助教]扬科维奇、[助教]郑智、[助教]P-卡纳瓦罗、[助教]阿巴雷拉、[助教]弗雷斯特、[队医]阿拉莫 | D12: 黑森林球场外场 | E12: 3000 | F12: 2848 | G12: =表2[[#This Row],[场均上座]]/表2[[#This Row],[座席数]] -> 0.94933333 | H12: =表2[[#This Row],[场均上座]]*95*20 -> 5411200 | I12: 4217 | J12: 加西亚荷兰人商会 600 | K12: 阿拉尼亚省金控集团 500 | L12: 100 | M12: 英国足总杯预选赛阶段第一圈
A13: 阿尔特弗雷奇流浪者 | B13: 玩家: 鬼才 | C13: 斯坦利·门佐、[助教]拉米罗、[助教]维奇戈、[助教]J-维米尔、[总监]托尔加汉、[体能]F-索托、[经理]N-德容 | D13: 沙波卢瓦球场 | E13: 16500 | F13: 9472 | G13: =表2[[#This Row],[场均上座]]/表2[[#This Row],[座席数]] -> 0.57406061 | H13: =表2[[#This Row],[场均上座]]*95*20 -> 17996800 | I13: 8200 | J13: 群岛省议会 700 | K13: 总统基金会 500 | L13: 3 | M13: 英国足总杯预选赛阶段第一圈
A14: 新南城 | B14: 玩家: 慕尼黑二次元 | C14: M-克洛泽、[助教]陆博飞、[助教]埃雷尔森、[助教]武磊、[助教]吉翔 | D14: 新泰体育中心专业足球场 | E14: 30000 | F14: 29839 | G14: =表2[[#This Row],[场均上座]]/表2[[#This Row],[座席数]] -> 0.99463333 | H14: =表2[[#This Row],[场均上座]]*95*20 -> 56694100 | I14: 7929 | J14: 南太平洋大学 400 | K14: 色温国立理工 400 | M14: /
A15: 诺维奇港 | B15: 玩家: 雀狗蛋 | C15: 伊拉奥拉、[体能]劳埃德、[分析]雷斯、[青训]R-科雷亚、[助教]S-库珀、[定位]D-瓦利亚、[领队]巴洛特利 | D15: 银河竞技场 | E15: 35000 | F15: 24259 | G15: =表2[[#This Row],[场均上座]]/表2[[#This Row],[座席数]] -> 0.69311429 | H15: =表2[[#This Row],[场均上座]]*95*20 -> 46092100 | I15: 4790 | J15: 斯波托普集团 700 | K15: Ikea Garcia 600 | L15: 100 | M15: 可征战法国杯第一圈
A16: 坎布尔新吕伐登 | B16: 玩家: 陈志 | C16: 博尔达拉斯、[助教]古伊萨、[助教]R-博达拉斯、[助教]H-维尔德斯、[体能]J-哈维尔、[门将]F-加兰、[青年]T-穆尼奥斯 | D16: 新吕伐登黑森林竞技场 | E16: 20000 | F16: 14129 | G16: =表2[[#This Row],[场均上座]]/表2[[#This Row],[座席数]] -> 0.70645 | H16: =表2[[#This Row],[场均上座]]*95*20 -> 26845100 | I16: 3578 | J16: 加西亚荷兰人商会 500 | K16: 拉阿纳矿业集团 500 | L16: 9 | M16: 可征战荷兰杯第一圈
A17: 东木市职业 | B17: 玩家：抖音pedri | C17: A-图兰、[助教]巴尔塔、[助教]戈尔、[助教]亚金、[助教]C-罗里洪、[青训]阿尔廷托普、[队医]S-坎贝尔 | D17: 东木市体育场 | E17: 30000 | F17: 13129 | G17: =表2[[#This Row],[场均上座]]/表2[[#This Row],[座席数]] -> 0.43763333 | H17: =表2[[#This Row],[场均上座]]*95*20 -> 24945100 | I17: 4352 | J17: 东木市议会 1000 | K17: 东木国信金控 300 | L17: 11 | M17: /
A18: 哈克竞技 | B18: 玩家：乌萨奇百宝箱 | C18: 斯卢茨基、别列祖茨基 | D18: 哈克足球场 | E18: 1000 | F18: 729 | G18: =表2[[#This Row],[场均上座]]/表2[[#This Row],[座席数]] -> 0.729 | H18: =表2[[#This Row],[场均上座]]*95*20 -> 1385100 | I18: 2603 | L18: 10 | M18: /
A19: 泰克马队 | B19: 玩家：抖音RMA | C19: 史蒂夫·波茨 | D19: 泰克足球场 | E19: 700 | F19: 178 | G19: =表2[[#This Row],[场均上座]]/表2[[#This Row],[座席数]] -> 0.25428571 | H19: =表2[[#This Row],[场均上座]]*95*20 -> 338200 | I19: 2449 | L19: 10 | M19: /
A20: 新泰泰山 | B20: 玩家：抖音云中歌 | C20: 韩鹏、[助教]金铉敏、[助教]A-洛佩斯、[助教]唐田、[门将]塞古拉、[体能]文虎一、[领队]宿茂臻 | D20: 新泰市泰山区泰山体育场 | E20: 28000 | F20: 10129 | G20: =表2[[#This Row],[场均上座]]/表2[[#This Row],[座席数]] -> 0.36175 | H20: =表2[[#This Row],[场均上座]]*95*20 -> 19245100 | I20: 2925 | J20: 色温省政府 400 | K20: 国内某财团 600 | L20: 90 | M20: /
A21: 三宝敦乐邦战士 | B21: 玩家：鹭菀苧 | C21: 加雷斯·索斯盖特、格林 | D21: 新阿尔米利亚提公园球场 | E21: 10000 | F21: 3316 | G21: =表2[[#This Row],[场均上座]]/表2[[#This Row],[座席数]] -> 0.3316 | H21: =表2[[#This Row],[场均上座]]*95*20 -> 6300400 | I21: 1701 | J21: 加西亚华人商会 400 | M21: /
A22: 泰克马联合 | B22: 玩家：抖音港迷 | C22: 凯克·塞蒂恩、[助教]F-佩德罗、[助教]陶伟、[助教]隋东亮、[助教]卡瓦略、[门将]D-奥里亚、[青训]徐云龙 | D22: 巴峰总统纪念球场 | E22: 16500 | F22: 15129 | G22: =表2[[#This Row],[场均上座]]/表2[[#This Row],[座席数]] -> 0.91690909 | H22: =表2[[#This Row],[场均上座]]*95*20 -> 28745100 | I22: 2915 | J22: 云南白药 200 | L22: 90 | M22: /
A23: 伊斯特伍德竞技 | D23: 伊斯特伍德球场 | E23: 5000 | G23: =表2[[#This Row],[场均上座]]/表2[[#This Row],[座席数]] -> 0 | H23: =表2[[#This Row],[场均上座]]*95*20 -> 0 | I23: 5000
A24: 朱马蓝色协进 | D24: 朱马第一中学操场 | E24: 600 | G24: =表2[[#This Row],[场均上座]]/表2[[#This Row],[座席数]] -> 0 | H24: =表2[[#This Row],[场均上座]]*95*20 -> 0 | I24: 5000
A25: 新利雅得新月 | B25: 抖音：79215334364 | C25: 车范根、[领队]车杜里、[助教]曹贵裁、[助教]李云在、[助教]徐正源、[体能]洪明甫 | D25: 新利雅得琛止苏丹球场 | E25: 15000 | F25: 6000 | G25: =表2[[#This Row],[场均上座]]/表2[[#This Row],[座席数]] -> 0.4 | H25: =表2[[#This Row],[场均上座]]*95*20 -> 11400000 | I25: 3227 | J25: PIF 1200 | K25: ARAMCO 200
A26: 拉阿纳 | B26: 抖音：Hanksjiang | C26: 彼得·斯特罗热 | D26: 拉阿纳体育场 | E26: 6000 | F26: 5859 | G26: =表2[[#This Row],[场均上座]]/表2[[#This Row],[座席数]] -> 0.9765 | H26: =表2[[#This Row],[场均上座]]*95*20 -> 11132100 | I26: 4635 | J26: 拉阿纳银行 500 | K26: 拉阿纳城投 300 | N26: =3430-180 -> 3250
A27: 伊丽莎白女王镇联合 | B27: 抖音Zones | C27: 斯科特·帕克、[进攻]W-鲁尼、[防守]霍兰德、[定位球]菲尔德、[门将]库尔、[队医]M-祖耶夫、[分析]J-奥利维 | D27: Whitecliff Stadium球场 | E27: 30000 | F27: 12000 | G27: =表2[[#This Row],[场均上座]]/表2[[#This Row],[座席数]] -> 0.4 | H27: =表2[[#This Row],[场均上座]]*95*20 -> 22800000 | I27: 2767 | J27: 女王镇议会 1000 | K27: 可喜安集团 600 | L27: 15
A28: 比斯恰捍卫者 | D28: 南萨乌萨乌奥体中心 | E28: 4000 | G28: =表2[[#This Row],[场均上座]]/表2[[#This Row],[座席数]] -> 0 | H28: =表2[[#This Row],[场均上座]]*95*20 -> 0 | I28: 5000
A29: 瓦巴萨朱树鸦B | B29: 玩家: 云龙 | C29: 麦克法兰 、杨戬 | D29: 瓦巴萨朱运动场 | E29: 900 | F29: 886 | G29: =表2[[#This Row],[场均上座]]/表2[[#This Row],[座席数]] -> 0.98444444 | H29: =表2[[#This Row],[场均上座]]*95*20 -> 1683400 | I29: 1414 | J29: Hyundai Garcia 400
A30: 首都-东木联合B | B30: 玩家：首都老哥&联合 | C30: D-黑金、[助教]D-施耐德、[助教]杰兰、[助教]莱曼、[助教]查普萨特、[青训]博雷尔、[队医]J-布劳 | D30: 国立竞技场外场 | E30: 50000 | F30: 992 | G30: =表2[[#This Row],[场均上座]]/表2[[#This Row],[座席数]] -> 0.01984 | H30: =表2[[#This Row],[场均上座]]*95*20 -> 1884800 | I30: 2499 | J30: 加西亚国家能投 400
A31: 东平雄鹰 | B31: 玩家：mason7 | D31: 东平县运动场 | E31: 4500 | F31: 1923 | G31: =表2[[#This Row],[场均上座]]/表2[[#This Row],[座席数]] -> 0.42733333 | H31: =表2[[#This Row],[场均上座]]*95*20 -> 3653700 | I31: 3663 | J31: 东平县议会 300
A32: 坎布尔新吕伐登B | B32: 玩家：维斯兰 | C32: 扬加、[进攻]卡罗尔、[队医]A-舒斯特尔、[助教]N-冈萨罗、[防守]L-梅迪纳、[分析]G-利蒙杰罗、[门将]I-沃克 | D32: 哈卡拉托特卡运动场 | E32: 700 | F32: 537 | G32: =表2[[#This Row],[场均上座]]/表2[[#This Row],[座席数]] -> 0.76714286 | H32: =表2[[#This Row],[场均上座]]*95*20 -> 1020300 | I32: 0 | J32: BYD Garcia 200
A33: 伊斯特伍德海岸线 | B33: 玩家：马雷克&瓦城 | C33: H-丰特、[进攻]S-格伯特、[战术]毛雷尔、[门将]菲迪斯、[防守]R-布纳多、[队医]伊提西亚、[青训]D-卢卡雷利 | D33: 国立大学东木校区体育场 | E33: 2000 | F33: 1359 | G33: =表2[[#This Row],[场均上座]]/表2[[#This Row],[座席数]] -> 0.6795 | H33: =表2[[#This Row],[场均上座]]*95*20 -> 2582100 | I33: 0 | J33: 马雷克商业银行 600 | K33: 马雷克农业银行 11
A34: 新法鲁大里斯本联盟 | B34: 玩家：椤楠 | C34: 索尔斯沙尔 | D34: 奎罗斯足球场 | E34: 8000 | G34: =表2[[#This Row],[场均上座]]/表2[[#This Row],[座席数]] -> 0 | H34: =表2[[#This Row],[场均上座]]*95*20 -> 0 | I34: 3342
A35: 新吕伐登猫头鹰镇 | B35: 玩家：T.5 | C35: 测试、理疗师 测试、助教 R-测试、运动主管 A-测试室、领队 A-测测测测、助教 C-得得得饿 | D35: 新吕伐登黑森林球场 | E35: 20000 | G35: =表2[[#This Row],[场均上座]]/表2[[#This Row],[座席数]] -> 0 | H35: =表2[[#This Row],[场均上座]]*95*20 -> 0 | I35: 3905
A36: 奥顿兰富力 | B36: 玩家：EEEEEd | C36: 肖恩·戴奇 | D36: 奥顿兰海岸球场 | E36: 6000 | F36: 5237 | G36: =表2[[#This Row],[场均上座]]/表2[[#This Row],[座席数]] -> 0.87283333 | H36: =表2[[#This Row],[场均上座]]*95*20 -> 9950300 | I36: 2633 | J36: Boeing 200 | K36: 洛马 100
A37: 新利雅得胜利 | B37: 玩家：我嘞个骚邦 | C37: 哈维、奥斯卡、大卫·普拉茨 | D37: 新利雅得琛止苏丹球场 | E37: 6000 | G37: =表2[[#This Row],[场均上座]]/表2[[#This Row],[座席数]] -> 0 | H37: =表2[[#This Row],[场均上座]]*95*20 -> 0 | I37: 507
A38: 北泰克马队 | B38: 玩家：A..2 | C38: 布鲁诺·拉巴迪亚 | D38: 泰克足球场 | E38: 700 | G38: =表2[[#This Row],[场均上座]]/表2[[#This Row],[座席数]] -> 0 | H38: =表2[[#This Row],[场均上座]]*95*20 -> 0 | I38: 2812
A39: 岱州东岳 | B39: 玩家：对方正在输入 | C39: 金大仪 | D39: 岱岳青年人足球场 | E39: 8000 | G39: =表2[[#This Row],[场均上座]]/表2[[#This Row],[座席数]] -> 0 | H39: =表2[[#This Row],[场均上座]]*95*20 -> 0 | I39: 2746
A40: 奥顿兰海鸥 | B40: 玩家：刘易斯汉密尔顿 | C40: 陈涛 | D40: 奥顿兰海岸球场 | E40: 6000 | F40: 3129 | G40: =表2[[#This Row],[场均上座]]/表2[[#This Row],[座席数]] -> 0.5215 | H40: =表2[[#This Row],[场均上座]]*95*20 -> 5945100 | I40: 1670
...

Sheet Sheet2
A1: 球队筛选 | X1: 马雷克青春之城
A2: 巴峰 | B2: 玩家 | C2: 教练组 | D2: 主场 | E2: 座席数 | F2: 场均上座 | G2: 上座率 | H2: 球场票房上赛季收入 | I2: 球队资金 | J2: 赞助商1 | K2: 赞助商2 | L2: 青训 | M2: 其他 | X2: 南太平洋大学
A3: =INDEX(球队表格!N:N, MATCH($A$2, 球队表格!A:A, 0)) -> 0 | B3: =INDEX(球队表格!B:B, MATCH($A$2, 球队表格!A:A, 0)) -> 玩家:抖音1.1595 | C3: =INDEX(球队表格!C:C, MATCH($A$2, 球队表格!A:A, 0)) -> F-卡纳瓦罗、[助教]扬科维奇、[助教]郑智、[助教]P-卡纳瓦罗、[助教]阿巴雷拉、[助教]弗雷斯特、[队医]阿拉莫 | D3: =INDEX(球队表格!D:D, MATCH($A$2, 球队表格!A:A, 0)) -> 黑森林球场外场 | E3: =INDEX(球队表格!E:E, MATCH($A$2, 球队表格!A:A, 0)) -> 3000 | F3: =INDEX(球队表格!F:F, MATCH($A$2, 球队表格!A:A, 0)) -> 2848 | G3: =INDEX(球队表格!G:G, MATCH($A$2, 球队表格!A:A, 0)) -> 0.94933333 | H3: =INDEX(球队表格!H:H, MATCH($A$2, 球队表格!A:A, 0)) -> 5411200 | I3: =INDEX(球队表格!I:I, MATCH($A$2, 球队表格!A:A, 0)) -> 4217 | J3: =INDEX(球队表格!J:J, MATCH($A$2, 球队表格!A:A, 0)) -> 加西亚荷兰人商会 600 | K3: =INDEX(球队表格!K:K, MATCH($A$2, 球队表格!A:A, 0)) -> 阿拉尼亚省金控集团 500 | L3: =INDEX(球队表格!L:L, MATCH($A$2, 球队表格!A:A, 0)) -> 100 | M3: =INDEX(球队表格!M:M, MATCH($A$2, 球队表格!A:A, 0)) -> 英国足总杯预选赛阶段第一圈 | X3: 三宝敦
D4: 均CA | E4: 均PA | F4: 最老登 | G4: 最小登 | I4: 年薪总和 | J4: 球队赛季末剩余资金 | K4: 仍处于可增长范围牛数 | L4: 均Age | X4: 皇家萨乌萨乌
D5: =AVERAGE(F10:F43) -> 118.42105 | E5: =AVERAGE(G10:G43) -> 126.21053 | F5: =MAX(B10:B43) -> 30 | G5: =MIN(B10:B43) -> 18 | I5: =SUM(I10:I43) -> 1101 | J5: =I3-I5 -> 3116 | K5: =COUNTIF(B10:B43, "<=26") -> 14 | L5: =AVERAGE(B10:B43) -> 23.315789 | X5: 安倍萨镇
X6: 哈贾丹太平洋人
X7: 首都守护者
X8: 比列竞技
A9: 球员名称 | B9: 年龄 | C9: 国家/地区籍 | D9: 身高 | E9: 体重 | F9: CA | G9: PA | H9: 位置 | I9: 年薪 | J9: 所在球队 | K9: 合约到期 | L9: 违约金 | M9: 合同类型 | N9: 合同备注 | X9: 瓦巴萨朱树鸦
A10: {=IFERROR( INDEX(球员数据库!A:A, SMALL(球员数据库!$O:$O, ROWS($A$10:A10)) ), "")} -> 斯坦利·约瑟夫 | B10: {=IFERROR( INDEX(球员数据库!B:B, SMALL(球员数据库!$O:$O, ROWS($A$10:A10)) ), "")} -> 24 | C10: {=IFERROR( INDEX(球员数据库!C:C, SMALL(球员数据库!$O:$O, ROWS($A$10:A10)) ), "")} -> 尼日利亚 | D10: {=IFERROR( INDEX(球员数据库!E:E, SMALL(球员数据库!$O:$O, ROWS($A$10:A10)) ), "")} -> 74 | E10: {=IFERROR( INDEX(球员数据库!D:D, SMALL(球员数据库!$O:$O, ROWS($A$10:A10)) ), "")} -> 184 | F10: {=IFERROR( INDEX(球员数据库!F:F, SMALL(球员数据库!$O:$O, ROWS($A$10:A10)) ), "")} -> 122 | G10: {=IFERROR( INDEX(球员数据库!G:G, SMALL(球员数据库!$O:$O, ROWS($A$10:A10)) ), "")} -> 122 | H10: =IFERROR( INDEX(球员数据库!H:H, SMALL(球员数据库!$O:$O, ROWS($A$10:H10)) ), "") -> 中卫，左边后卫 | I10: =IFERROR( INDEX(球员数据库!I:I, SMALL(球员数据库!$O:$O, ROWS($A$10:H10)) ), "") -> 80 | J10: =IFERROR( INDEX(球员数据库!J:J, SMALL(球员数据库!$O:$O, ROWS($A$10:J10)) ), "") -> 巴峰 | K10: =IFERROR( INDEX(球员数据库!K:K, SMALL(球员数据库!$O:$O, ROWS($A$10:J10)) ), "") -> 5 | L10: =IFERROR( INDEX(球员数据库!L:L, SMALL(球员数据库!$O:$O, ROWS($A$10:J10)) ), "") -> 400 | M10: =IFERROR( INDEX(球员数据库!M:M, SMALL(球员数据库!$O:$O, ROWS($A$10:M10)) ), "") -> 全额保障 | N10: =IFERROR( INDEX(球员数据库!N:N, SMALL(球员数据库!$O:$O, ROWS($A$10:M10)) ), "") -> 0 | X10: 穆拉哈西部
A11: {=IFERROR( INDEX(球员数据库!A:A, SMALL(球员数据库!$O:$O, ROWS($A$10:A11)) ), "")} -> 吉先·萨米 | B11: {=IFERROR( INDEX(球员数据库!B:B, SMALL(球员数据库!$O:$O, ROWS($A$10:A11)) ), "")} -> 27 | C11: {=IFERROR( INDEX(球员数据库!C:C, SMALL(球员数据库!$O:$O, ROWS($A$10:A11)) ), "")} -> 斐济 | D11: {=IFERROR( INDEX(球员数据库!E:E, SMALL(球员数据库!$O:$O, ROWS($A$10:A11)) ), "")} -> 75 | E11: {=IFERROR( INDEX(球员数据库!D:D, SMALL(球员数据库!$O:$O, ROWS($A$10:A11)) ), "")} -> 178 | F11: {=IFERROR( INDEX(球员数据库!F:F, SMALL(球员数据库!$O:$O, ROWS($A$10:A11)) ), "")} -> 74 | G11: {=IFERROR( INDEX(球员数据库!G:G, SMALL(球员数据库!$O:$O, ROWS($A$10:A11)) ), "")} -> 74 | H11: =IFERROR( INDEX(球员数据库!H:H, SMALL(球员数据库!$O:$O, ROWS($A$10:H11)) ), "") -> 左右边后卫，左右边翼卫 | I11: =IFERROR( INDEX(球员数据库!I:I, SMALL(球员数据库!$O:$O, ROWS($A$10:H11)) ), "") -> 24 | J11: =IFERROR( INDEX(球员数据库!J:J, SMALL(球员数据库!$O:$O, ROWS($A$10:J11)) ), "") -> 巴峰 | K11: =IFERROR( INDEX(球员数据库!K:K, SMALL(球员数据库!$O:$O, ROWS($A$10:J11)) ), "") -> 5 | L11: =IFERROR( INDEX(球员数据库!L:L, SMALL(球员数据库!$O:$O, ROWS($A$10:J11)) ), "") -> 120 | M11: =IFERROR( INDEX(球员数据库!M:M, SMALL(球员数据库!$O:$O, ROWS($A$10:M11)) ), "") -> 半保障 | N11: =IFERROR( INDEX(球员数据库!N:N, SMALL(球员数据库!$O:$O, ROWS($A$10:M11)) ), "") -> 0 | X11: 巴峰
A12: {=IFERROR( INDEX(球员数据库!A:A, SMALL(球员数据库!$O:$O, ROWS($A$10:A12)) ), "")} -> 弗雷德里希·穆勒 | B12: {=IFERROR( INDEX(球员数据库!B:B, SMALL(球员数据库!$O:$O, ROWS($A$10:A12)) ), "")} -> 22 | C12: {=IFERROR( INDEX(球员数据库!C:C, SMALL(球员数据库!$O:$O, ROWS($A$10:A12)) ), "")} -> 德国 | D12: {=IFERROR( INDEX(球员数据库!E:E, SMALL(球员数据库!$O:$O, ROWS($A$10:A12)) ), "")} -> 75 | E12: {=IFERROR( INDEX(球员数据库!D:D, SMALL(球员数据库!$O:$O, ROWS($A$10:A12)) ), "")} -> 169 | F12: {=IFERROR( INDEX(球员数据库!F:F, SMALL(球员数据库!$O:$O, ROWS($A$10:A12)) ), "")} -> 124 | G12: {=IFERROR( INDEX(球员数据库!G:G, SMALL(球员数据库!$O:$O, ROWS($A$10:A12)) ), "")} -> 140 | H12: =IFERROR( INDEX(球员数据库!H:H, SMALL(球员数据库!$O:$O, ROWS($A$10:H12)) ), "") -> 中场，左边中场 | I12: =IFERROR( INDEX(球员数据库!I:I, SMALL(球员数据库!$O:$O, ROWS($A$10:H12)) ), "") -> 100 | J12: =IFERROR( INDEX(球员数据库!J:J, SMALL(球员数据库!$O:$O, ROWS($A$10:J12)) ), "") -> 巴峰 | K12: =IFERROR( INDEX(球员数据库!K:K, SMALL(球员数据库!$O:$O, ROWS($A$10:J12)) ), "") -> 6 | L12: =IFERROR( INDEX(球员数据库!L:L, SMALL(球员数据库!$O:$O, ROWS($A$10:J12)) ), "") -> 500 | M12: =IFERROR( INDEX(球员数据库!M:M, SMALL(球员数据库!$O:$O, ROWS($A$10:M12)) ), "") -> 全额保障 | N12: =IFERROR( INDEX(球员数据库!N:N, SMALL(球员数据库!$O:$O, ROWS($A$10:M12)) ), "") -> 0 | X12: 阿尔特弗雷奇流浪者
A13: {=IFERROR( INDEX(球员数据库!A:A, SMALL(球员数据库!$O:$O, ROWS($A$10:A13)) ), "")} -> 张国哲（小） | B13: {=IFERROR( INDEX(球员数据库!B:B, SMALL(球员数据库!$O:$O, ROWS($A$10:A13)) ), "")} -> 29 | C13: {=IFERROR( INDEX(球员数据库!C:C, SMALL(球员数据库!$O:$O, ROWS($A$10:A13)) ), "")} -> 朝鲜 | D13: {=IFERROR( INDEX(球员数据库!E:E, SMALL(球员数据库!$O:$O, ROWS($A$10:A13)) ), "")} -> 75 | E13: {=IFERROR( INDEX(球员数据库!D:D, SMALL(球员数据库!$O:$O, ROWS($A$10:A13)) ), "")} -> 177 | F13: {=IFERROR( INDEX(球员数据库!F:F, SMALL(球员数据库!$O:$O, ROWS($A$10:A13)) ), "")} -> 98 | G13: {=IFERROR( INDEX(球员数据库!G:G, SMALL(球员数据库!$O:$O, ROWS($A$10:A13)) ), "")} -> 110 | H13: =IFERROR( INDEX(球员数据库!H:H, SMALL(球员数据库!$O:$O, ROWS($A$10:H13)) ), "") -> 左边锋，中场，左边后卫 | I13: =IFERROR( INDEX(球员数据库!I:I, SMALL(球员数据库!$O:$O, ROWS($A$10:H13)) ), "") -> 25 | J13: =IFERROR( INDEX(球员数据库!J:J, SMALL(球员数据库!$O:$O, ROWS($A$10:J13)) ), "") -> 巴峰 | K13: =IFERROR( INDEX(球员数据库!K:K, SMALL(球员数据库!$O:$O, ROWS($A$10:J13)) ), "") -> 5 | L13: =IFERROR( INDEX(球员数据库!L:L, SMALL(球员数据库!$O:$O, ROWS($A$10:J13)) ), "") -> 125 | M13: =IFERROR( INDEX(球员数据库!M:M, SMALL(球员数据库!$O:$O, ROWS($A$10:M13)) ), "") -> 全额保障 | N13: =IFERROR( INDEX(球员数据库!N:N, SMALL(球员数据库!$O:$O, ROWS($A$10:M13)) ), "") -> 0 | X13: 新南城
A14: {=IFERROR( INDEX(球员数据库!A:A, SMALL(球员数据库!$O:$O, ROWS($A$10:A14)) ), "")} -> 金成日 | B14: {=IFERROR( INDEX(球员数据库!B:B, SMALL(球员数据库!$O:$O, ROWS($A$10:A14)) ), "")} -> 22 | C14: {=IFERROR( INDEX(球员数据库!C:C, SMALL(球员数据库!$O:$O, ROWS($A$10:A14)) ), "")} -> 朝鲜 | D14: {=IFERROR( INDEX(球员数据库!E:E, SMALL(球员数据库!$O:$O, ROWS($A$10:A14)) ), "")} -> 78 | E14: {=IFERROR( INDEX(球员数据库!D:D, SMALL(球员数据库!$O:$O, ROWS($A$10:A14)) ), "")} -> 182 | F14: {=IFERROR( INDEX(球员数据库!F:F, SMALL(球员数据库!$O:$O, ROWS($A$10:A14)) ), "")} -> 132 | G14: {=IFERROR( INDEX(球员数据库!G:G, SMALL(球员数据库!$O:$O, ROWS($A$10:A14)) ), "")} -> 132 | H14: =IFERROR( INDEX(球员数据库!H:H, SMALL(球员数据库!$O:$O, ROWS($A$10:H14)) ), "") -> 后腰，中场 | I14: =IFERROR( INDEX(球员数据库!I:I, SMALL(球员数据库!$O:$O, ROWS($A$10:H14)) ), "") -> 24 | J14: =IFERROR( INDEX(球员数据库!J:J, SMALL(球员数据库!$O:$O, ROWS($A$10:J14)) ), "") -> 巴峰 | K14: =IFERROR( INDEX(球员数据库!K:K, SMALL(球员数据库!$O:$O, ROWS($A$10:J14)) ), "") -> 7 | L14: =IFERROR( INDEX(球员数据库!L:L, SMALL(球员数据库!$O:$O, ROWS($A$10:J14)) ), "") -> 120 | M14: =IFERROR( INDEX(球员数据库!M:M, SMALL(球员数据库!$O:$O, ROWS($A$10:M14)) ), "") -> 全额保障 | N14: =IFERROR( INDEX(球员数据库!N:N, SMALL(球员数据库!$O:$O, ROWS($A$10:M14)) ), "") -> 0 | X14: 诺维奇港
A15: {=IFERROR( INDEX(球员数据库!A:A, SMALL(球员数据库!$O:$O, ROWS($A$10:A15)) ), "")} -> 博·勒鲁瓦 | B15: {=IFERROR( INDEX(球员数据库!B:B, SMALL(球员数据库!$O:$O, ROWS($A$10:A15)) ), "")} -> 23 | C15: {=IFERROR( INDEX(球员数据库!C:C, SMALL(球员数据库!$O:$O, ROWS($A$10:A15)) ), "")} -> 中国 | D15: {=IFERROR( INDEX(球员数据库!E:E, SMALL(球员数据库!$O:$O, ROWS($A$10:A15)) ), "")} -> 75 | E15: {=IFERROR( INDEX(球员数据库!D:D, SMALL(球员数据库!$O:$O, ROWS($A$10:A15)) ), "")} -> 178 | F15: {=IFERROR( INDEX(球员数据库!F:F, SMALL(球员数据库!$O:$O, ROWS($A$10:A15)) ), "")} -> 126 | G15: {=IFERROR( INDEX(球员数据库!G:G, SMALL(球员数据库!$O:$O, ROWS($A$10:A15)) ), "")} -> 136 | H15: =IFERROR( INDEX(球员数据库!H:H, SMALL(球员数据库!$O:$O, ROWS($A$10:H15)) ), "") -> 中场 | I15: =IFERROR( INDEX(球员数据库!I:I, SMALL(球员数据库!$O:$O, ROWS($A$10:H15)) ), "") -> 120 | J15: =IFERROR( INDEX(球员数据库!J:J, SMALL(球员数据库!$O:$O, ROWS($A$10:J15)) ), "") -> 巴峰 | K15: =IFERROR( INDEX(球员数据库!K:K, SMALL(球员数据库!$O:$O, ROWS($A$10:J15)) ), "") -> 5 | L15: =IFERROR( INDEX(球员数据库!L:L, SMALL(球员数据库!$O:$O, ROWS($A$10:J15)) ), "") -> 600 | M15: =IFERROR( INDEX(球员数据库!M:M, SMALL(球员数据库!$O:$O, ROWS($A$10:M15)) ), "") -> 全额保障 | N15: =IFERROR( INDEX(球员数据库!N:N, SMALL(球员数据库!$O:$O, ROWS($A$10:M15)) ), "") -> 0 | X15: 坎布尔新吕伐登
A16: {=IFERROR( INDEX(球员数据库!A:A, SMALL(球员数据库!$O:$O, ROWS($A$10:A16)) ), "")} -> 维罗尼·普罗布斯特 | B16: {=IFERROR( INDEX(球员数据库!B:B, SMALL(球员数据库!$O:$O, ROWS($A$10:A16)) ), "")} -> 23 | C16: {=IFERROR( INDEX(球员数据库!C:C, SMALL(球员数据库!$O:$O, ROWS($A$10:A16)) ), "")} -> 加西亚，德国 | D16: {=IFERROR( INDEX(球员数据库!E:E, SMALL(球员数据库!$O:$O, ROWS($A$10:A16)) ), "")} -> 92 | E16: {=IFERROR( INDEX(球员数据库!D:D, SMALL(球员数据库!$O:$O, ROWS($A$10:A16)) ), "")} -> 202 | F16: {=IFERROR( INDEX(球员数据库!F:F, SMALL(球员数据库!$O:$O, ROWS($A$10:A16)) ), "")} -> 124 | G16: {=IFERROR( INDEX(球员数据库!G:G, SMALL(球员数据库!$O:$O, ROWS($A$10:A16)) ), "")} -> 124 | H16: =IFERROR( INDEX(球员数据库!H:H, SMALL(球员数据库!$O:$O, ROWS($A$10:H16)) ), "") -> 前锋 | I16: =IFERROR( INDEX(球员数据库!I:I, SMALL(球员数据库!$O:$O, ROWS($A$10:H16)) ), "") -> 100 | J16: =IFERROR( INDEX(球员数据库!J:J, SMALL(球员数据库!$O:$O, ROWS($A$10:J16)) ), "") -> 巴峰 | K16: =IFERROR( INDEX(球员数据库!K:K, SMALL(球员数据库!$O:$O, ROWS($A$10:J16)) ), "") -> 8 | L16: =IFERROR( INDEX(球员数据库!L:L, SMALL(球员数据库!$O:$O, ROWS($A$10:J16)) ), "") -> 500 | M16: =IFERROR( INDEX(球员数据库!M:M, SMALL(球员数据库!$O:$O, ROWS($A$10:M16)) ), "") -> 全额保障 | N16: =IFERROR( INDEX(球员数据库!N:N, SMALL(球员数据库!$O:$O, ROWS($A$10:M16)) ), "") -> 0 | X16: 泰克马职业
A17: {=IFERROR( INDEX(球员数据库!A:A, SMALL(球员数据库!$O:$O, ROWS($A$10:A17)) ), "")} -> 安格尔·图伊马莱桑加 | B17: {=IFERROR( INDEX(球员数据库!B:B, SMALL(球员数据库!$O:$O, ROWS($A$10:A17)) ), "")} -> 21 | C17: {=IFERROR( INDEX(球员数据库!C:C, SMALL(球员数据库!$O:$O, ROWS($A$10:A17)) ), "")} -> 加西亚，汤加 | D17: {=IFERROR( INDEX(球员数据库!E:E, SMALL(球员数据库!$O:$O, ROWS($A$10:A17)) ), "")} -> 86 | E17: {=IFERROR( INDEX(球员数据库!D:D, SMALL(球员数据库!$O:$O, ROWS($A$10:A17)) ), "")} -> 185 | F17: {=IFERROR( INDEX(球员数据库!F:F, SMALL(球员数据库!$O:$O, ROWS($A$10:A17)) ), "")} -> 121 | G17: {=IFERROR( INDEX(球员数据库!G:G, SMALL(球员数据库!$O:$O, ROWS($A$10:A17)) ), "")} -> 121 | H17: =IFERROR( INDEX(球员数据库!H:H, SMALL(球员数据库!$O:$O, ROWS($A$10:H17)) ), "") -> 中卫 | I17: =IFERROR( INDEX(球员数据库!I:I, SMALL(球员数据库!$O:$O, ROWS($A$10:H17)) ), "") -> 24 | J17: =IFERROR( INDEX(球员数据库!J:J, SMALL(球员数据库!$O:$O, ROWS($A$10:J17)) ), "") -> 巴峰 | K17: =IFERROR( INDEX(球员数据库!K:K, SMALL(球员数据库!$O:$O, ROWS($A$10:J17)) ), "") -> 6 | L17: =IFERROR( INDEX(球员数据库!L:L, SMALL(球员数据库!$O:$O, ROWS($A$10:J17)) ), "") -> 120 | M17: =IFERROR( INDEX(球员数据库!M:M, SMALL(球员数据库!$O:$O, ROWS($A$10:M17)) ), "") -> 半保障 | N17: =IFERROR( INDEX(球员数据库!N:N, SMALL(球员数据库!$O:$O, ROWS($A$10:M17)) ), "") -> 0 | X17: 哈瓦鲁海岸
A18: {=IFERROR( INDEX(球员数据库!A:A, SMALL(球员数据库!$O:$O, ROWS($A$10:A18)) ), "")} -> 约翰森·罗阿德 | B18: {=IFERROR( INDEX(球员数据库!B:B, SMALL(球员数据库!$O:$O, ROWS($A$10:A18)) ), "")} -> 20 | C18: {=IFERROR( INDEX(球员数据库!C:C, SMALL(球员数据库!$O:$O, ROWS($A$10:A18)) ), "")} -> 加西亚 | D18: {=IFERROR( INDEX(球员数据库!E:E, SMALL(球员数据库!$O:$O, ROWS($A$10:A18)) ), "")} -> 78 | E18: {=IFERROR( INDEX(球员数据库!D:D, SMALL(球员数据库!$O:$O, ROWS($A$10:A18)) ), "")} -> 187 | F18: {=IFERROR( INDEX(球员数据库!F:F, SMALL(球员数据库!$O:$O, ROWS($A$10:A18)) ), "")} -> 124 | G18: {=IFERROR( INDEX(球员数据库!G:G, SMALL(球员数据库!$O:$O, ROWS($A$10:A18)) ), "")} -> 124 | H18: =IFERROR( INDEX(球员数据库!H:H, SMALL(球员数据库!$O:$O, ROWS($A$10:H18)) ), "") -> 中卫，中锋 | I18: =IFERROR( INDEX(球员数据库!I:I, SMALL(球员数据库!$O:$O, ROWS($A$10:H18)) ), "") -> 24 | J18: =IFERROR( INDEX(球员数据库!J:J, SMALL(球员数据库!$O:$O, ROWS($A$10:J18)) ), "") -> 巴峰 | K18: =IFERROR( INDEX(球员数据库!K:K, SMALL(球员数据库!$O:$O, ROWS($A$10:J18)) ), "") -> 5 | L18: =IFERROR( INDEX(球员数据库!L:L, SMALL(球员数据库!$O:$O, ROWS($A$10:J18)) ), "") -> 120 | M18: =IFERROR( INDEX(球员数据库!M:M, SMALL(球员数据库!$O:$O, ROWS($A$10:M18)) ), "") -> 半保障 | N18: =IFERROR( INDEX(球员数据库!N:N, SMALL(球员数据库!$O:$O, ROWS($A$10:M18)) ), "") -> 0 | X18: 泰克马队
A19: {=IFERROR( INDEX(球员数据库!A:A, SMALL(球员数据库!$O:$O, ROWS($A$10:A19)) ), "")} -> 栾毅 | B19: {=IFERROR( INDEX(球员数据库!B:B, SMALL(球员数据库!$O:$O, ROWS($A$10:A19)) ), "")} -> 21 | C19: {=IFERROR( INDEX(球员数据库!C:C, SMALL(球员数据库!$O:$O, ROWS($A$10:A19)) ), "")} -> 中国 | D19: {=IFERROR( INDEX(球员数据库!E:E, SMALL(球员数据库!$O:$O, ROWS($A$10:A19)) ), "")} -> 70 | E19: {=IFERROR( INDEX(球员数据库!D:D, SMALL(球员数据库!$O:$O, ROWS($A$10:A19)) ), "")} -> 195 | F19: {=IFERROR( INDEX(球员数据库!F:F, SMALL(球员数据库!$O:$O, ROWS($A$10:A19)) ), "")} -> 106 | G19: {=IFERROR( INDEX(球员数据库!G:G, SMALL(球员数据库!$O:$O, ROWS($A$10:A19)) ), "")} -> 106 | H19: =IFERROR( INDEX(球员数据库!H:H, SMALL(球员数据库!$O:$O, ROWS($A$10:H19)) ), "") -> 门将 | I19: =IFERROR( INDEX(球员数据库!I:I, SMALL(球员数据库!$O:$O, ROWS($A$10:H19)) ), "") -> 24 | J19: =IFERROR( INDEX(球员数据库!J:J, SMALL(球员数据库!$O:$O, ROWS($A$10:J19)) ), "") -> 巴峰 | K19: =IFERROR( INDEX(球员数据库!K:K, SMALL(球员数据库!$O:$O, ROWS($A$10:J19)) ), "") -> 5 | L19: =IFERROR( INDEX(球员数据库!L:L, SMALL(球员数据库!$O:$O, ROWS($A$10:J19)) ), "") -> 120 | M19: =IFERROR( INDEX(球员数据库!M:M, SMALL(球员数据库!$O:$O, ROWS($A$10:M19)) ), "") -> 全额保障 | N19: =IFERROR( INDEX(球员数据库!N:N, SMALL(球员数据库!$O:$O, ROWS($A$10:M19)) ), "") -> 0 | X19: 新泰泰山
A20: {=IFERROR( INDEX(球员数据库!A:A, SMALL(球员数据库!$O:$O, ROWS($A$10:A20)) ), "")} -> 阿贝尔·霍查 | B20: {=IFERROR( INDEX(球员数据库!B:B, SMALL(球员数据库!$O:$O, ROWS($A$10:A20)) ), "")} -> 28 | C20: {=IFERROR( INDEX(球员数据库!C:C, SMALL(球员数据库!$O:$O, ROWS($A$10:A20)) ), "")} -> 阿尔巴尼亚 | D20: {=IFERROR( INDEX(球员数据库!E:E, SMALL(球员数据库!$O:$O, ROWS($A$10:A20)) ), "")} -> 74 | E20: {=IFERROR( INDEX(球员数据库!D:D, SMALL(球员数据库!$O:$O, ROWS($A$10:A20)) ), "")} -> 178 | F20: {=IFERROR( INDEX(球员数据库!F:F, SMALL(球员数据库!$O:$O, ROWS($A$10:A20)) ), "")} -> 118 | G20: {=IFERROR( INDEX(球员数据库!G:G, SMALL(球员数据库!$O:$O, ROWS($A$10:A20)) ), "")} -> 119 | H20: =IFERROR( INDEX(球员数据库!H:H, SMALL(球员数据库!$O:$O, ROWS($A$10:H20)) ), "") -> 左边锋 | I20: =IFERROR( INDEX(球员数据库!I:I, SMALL(球员数据库!$O:$O, ROWS($A$10:H20)) ), "") -> 60 | J20: =IFERROR( INDEX(球员数据库!J:J, SMALL(球员数据库!$O:$O, ROWS($A$10:J20)) ), "") -> 巴峰 | K20: =IFERROR( INDEX(球员数据库!K:K, SMALL(球员数据库!$O:$O, ROWS($A$10:J20)) ), "") -> 6 | L20: =IFERROR( INDEX(球员数据库!L:L, SMALL(球员数据库!$O:$O, ROWS($A$10:J20)) ), "") -> 300 | M20: =IFERROR( INDEX(球员数据库!M:M, SMALL(球员数据库!$O:$O, ROWS($A$10:M20)) ), "") -> 全额保障 | N20: =IFERROR( INDEX(球员数据库!N:N, SMALL(球员数据库!$O:$O, ROWS($A$10:M20)) ), "") -> 0 | X20: 哈阿莱卓越钢管
A21: {=IFERROR( INDEX(球员数据库!A:A, SMALL(球员数据库!$O:$O, ROWS($A$10:A21)) ), "")} -> 维萨尔·贝卡伊 | B21: {=IFERROR( INDEX(球员数据库!B:B, SMALL(球员数据库!$O:$O, ROWS($A$10:A21)) ), "")} -> 30 | C21: {=IFERROR( INDEX(球员数据库!C:C, SMALL(球员数据库!$O:$O, ROWS($A$10:A21)) ), "")} -> 波黑 | D21: {=IFERROR( INDEX(球员数据库!E:E, SMALL(球员数据库!$O:$O, ROWS($A$10:A21)) ), "")} -> 0 | E21: {=IFERROR( INDEX(球员数据库!D:D, SMALL(球员数据库!$O:$O, ROWS($A$10:A21)) ), "")} -> 0 | F21: {=IFERROR( INDEX(球员数据库!F:F, SMALL(球员数据库!$O:$O, ROWS($A$10:A21)) ), "")} -> 110 | G21: {=IFERROR( INDEX(球员数据库!G:G, SMALL(球员数据库!$O:$O, ROWS($A$10:A21)) ), "")} -> 116 | H21: =IFERROR( INDEX(球员数据库!H:H, SMALL(球员数据库!$O:$O, ROWS($A$10:H21)) ), "") -> 门将 | I21: =IFERROR( INDEX(球员数据库!I:I, SMALL(球员数据库!$O:$O, ROWS($A$10:H21)) ), "") -> 40 | J21: =IFERROR( INDEX(球员数据库!J:J, SMALL(球员数据库!$O:$O, ROWS($A$10:J21)) ), "") -> 巴峰 | K21: =IFERROR( INDEX(球员数据库!K:K, SMALL(球员数据库!$O:$O, ROWS($A$10:J21)) ), "") -> 5 | L21: =IFERROR( INDEX(球员数据库!L:L, SMALL(球员数据库!$O:$O, ROWS($A$10:J21)) ), "") -> 200 | M21: =IFERROR( INDEX(球员数据库!M:M, SMALL(球员数据库!$O:$O, ROWS($A$10:M21)) ), "") -> 半保障 | N21: =IFERROR( INDEX(球员数据库!N:N, SMALL(球员数据库!$O:$O, ROWS($A$10:M21)) ), "") -> 0 | X21: 泰克马联合
... A43: {=IFERROR( INDEX(球员数据库!A:A, SMALL(球员数据库!$O:$O, ROWS($A$10:A43)) ), "")} | B43: {=IFERROR( INDEX(球员数据库!B:B, SMALL(球员数据库!$O:$O, ROWS($A$10:A43)) ), "")} | C43: {=IFERROR( INDEX(球员数据库!C:C, SMALL(球员数据库!$O:$O, ROWS($A$10:A43)) ), "")} | D43: {=IFERROR( INDEX(球员数据库!E:E, SMALL(球员数据库!$O:$O, ROWS($A$10:A43)) ), "")} | E43: {=IFERROR( INDEX(球员数据库!D:D, SMALL(球员数据库!$O:$O, ROWS($A$10:A43)) ), "")} | F43: {=IFERROR( INDEX(球员数据库!F:F, SMALL(球员数据库!$O:$O, ROWS($A$10:A43)) ), "")} | G43: {=IFERROR( INDEX(球员数据库!G:G, SMALL(球员数据库!$O:$O, ROWS($A$10:A43)) ), "")} | H43: =IFERROR( INDEX(球员数据库!H:H, SMALL(球员数据库!$O:$O, ROWS($A$10:H43)) ), "") | I43: =IFERROR( INDEX(球员数据库!I:I, SMALL(球员数据库!$O:$O, ROWS($A$10:H43)) ), "") | J43: =IFERROR( INDEX(球员数据库!J:J, SMALL(球员数据库!$O:$O, ROWS($A$10:J43)) ), "") | K43: =IFERROR( INDEX(球员数据库!K:K, SMALL(球员数据库!$O:$O, ROWS($A$10:J43)) ), "") | L43: =IFERROR( INDEX(球员数据库!L:L, SMALL(球员数据库!$O:$O, ROWS($A$10:J43)) ), "") | M43: =IFERROR( INDEX(球员数据库!M:M, SMALL(球员数据库!$O:$O, ROWS($A$10:M43)) ), "") | N43: =IFERROR( INDEX(球员数据库!N:N, SMALL(球员数据库!$O:$O, ROWS($A$10:M43)) ), "") | X43: 泰克马职业
X44: 斯波托普城市
